Workbook

Sheet Shortcuts
A2: Follow up | B2: Clarification required on remaining items
A4: GC_Bank_Statements | B4: Bank statement export
A6: TB 2017 | B6: Trial balance - 2017
A7: GL 2017 | B7: General ledger - 2017
A9: TB 2016 | B9: Trial balance - 2016
A10: GL 2016 | B10: General ledger - 2016
A12: WORKINGS | B12: Workings and calculations
A14: Cover | B14: AFS - Cover page
A15: General info | B15: AFS - General information
A16: Index | B16: AFS - Index of contents
A17: Resp&Approval | B17: AFS - Committee's responsibility and approval
A18: Treasurer report | B18: AFS - Treasurer report
... A24: Notes | B24: AFS - Notes to the annual financial statements

Sheet Follow up
A2: COVER PAGE
B3: confirm date of issue, comfortable to show that it was issued on 25 April 2018, Eventually would like to bring that down to within 3 months after YE. Take into account that the composition of the committee should reflect as it currently stands (include resignation of S Khan and appointment of Chris Prinsloo as the interim chair and Alida Naude as interim secretary)
A5: GENERAL INFO
B6: Date of incorporation - no signed copy of constitution available to confirm date, date taken as the date upon which the bank account was opened. (Constitution will be amended to align with new CSA constitution adopted in February 2018
A8: CONSOLIDATED INCOME STATEMENT (included in treasurer report) or seperately disclosed if it should not be included in the scope of the audit
A9: CGC | B9: Information obtained from regions need to be at a more granular leve. Cannot just present consolidated total income. At a bare minimum need to disclose the income generated from the various income streams at the regions' disposal. If required treasurer might want to interogate further level of detail for reasonability
A10: All | B10: Should we consider classifying expenses by nature - ie expenses incurred in running administrative functions and expenses incurred in executing on the objectives per the constitutions of the regions and the province? Would give public at large a more transparent view of what value is being added to the sport
A11: All | B11: If more detail requested around certain expence categories, are there original source documents available to support these expenses that adds up to the total (are there expenses that cannot be substantiated?) If so these should be Categorised in the correct category, but clearly differentiated as expenses for which no supporting documents are available in the income statement notes.
A12: CGC | B12: Salaries - Registered employees? Compliance with payroll taxes?
A13: CGC | B13: Management consulting fees - What is this made up of? Related party? What was the need for consulting on if there are salaried employees? Single largest expense line item, if questioned can this be explained?
A14: CGC, GN | B14: Honarariums? What are these expenses made up of? What is the purpose? Clarification required.
A16: Check:
A17: Fix page numbering once finalised
A18: Registered address? As Shahad resigned and 30A Dias crescent no longer the office
A19: Confirm discipline heads (Meeting date where elected?)
A20: Statement of cash flows note wording …
A21: Summary of major resolutions passed at meetings if any
A23: Logo for GC for cover page of financials
A25: Constitutional alignment to new constitution of CSA
A27: Website?
A28: Formal notice of AGM in the manner prescribed
A30: Amend constitution to clarify what audit entails. (Although CSA has similar vague wording, assumed to be an audit performed by a registered auditor under the ISA's
A32: Include provisions for different type of resolutions (ordinary and special)
... A43: Possibly include segment dealing with powers of officcials in AFS

Sheet Budget 2018FY
E2: 2018/2019 year
B3: Description | F3: Road champs | G3: Track champs | H3: MTB champs | I3: BMX champs
B5: Income
B6: Rider entry fees | E6: 94080 | F6: =E6 -> 94080 | G6: 27750
B7: Ancillary - food and ddrink sales | G7: 5271.6
B9: Expenses | F9: =SUM(F10:F33) -> 106452.91 | G9: =SUM(G10:G37) -> 34140.49
B10: Insurance covered by CSA
B11: Medals | E11: 4550.98 | F11: =E11*1.06^2 -> 5113.4811 | G11: 6184.5
B12: Medics ER24 | E12: 7612.35 | F12: =E12*1.06^2 -> 8553.2365 | G12: 9030.51
B13: Mardo Foto's | E13: 4500 | F13: =E13*1.06^2 -> 5056.2
B14: Refunds | E14: 15510
B17: Cycle Events 10% fee of total entries line entries
B18: 10% on entries + Vat at 14% | E18: 12738.36 | F18: =E18*1.06^2 -> 14312.821
B19: Bank charges = Vat | E19: 4338.5
B20: Barriers
B21: Officials | E21: 25935 | F21: =E21*1.06^2 -> 29140.566 | G21: 10000
B22: Sound
B23: Safety officer | E23: 4634.1 | F23: =E23*1.06^2 -> 5206.8748
B24: Marshalls | E24: 2052 | F24: =E24*1.06^2 -> 2305.6272
B25: Motor Cycles (Think Bike) | E25: 7500 | F25: =E25*1.06^2 -> 8427
B26: Food and Drinks (Medics, Traffic, Officials, Think Bike) | E26: 4693.38 | F26: =E26*1.06^2 -> 5273.4818 | G26: 1326.12
B27: Pins, Envelopes, Race numbers, Tel calls | E27: 2000 | F27: =E27*1.06^2 -> 2247.2 | G27: 986.69
B28: Petrol - Route finding, marking, meetings, casuals | E28: 2500 | F28: =E28*1.06^2 -> 2809
B29: Venue Hire Boswell wilkie Circus | E29: 4560 | F29: =E29*1.06^2 -> 5123.616
B30: Midvaal Traffic - Saturday and Sunday | E30: 9473 | F30: =E30*1.06^2 -> 10643.863
B31: Dept of Road and Transport | E31: 100 | F31: =E31*1.06^2 -> 112.36
B32: Signage | E32: 1893.54 | F32: =E32*1.06^2 -> 2127.5815
B33: Organizers fee | E33: 39900
B34: Car guards | G34: 2415
B35: Wors Rolls | G35: 1758.84
B36: Announcer | G36: 1500
B37: Thank you Gifts | G37: 938.83
B39: Net shortfall | F39: =F6-F9 -> -12372.909 | G39: =G6-G9+G7 -> -1118.89
B40: Assumed worst case | F40: -50000 | G40: -30000 | H40: -80000
B41: equally amongst 4 regions | F41: =F40/4 -> -12500 | G41: =G40/4 -> -7500 | H41: =H40/4 -> -20000 | I41: ?

Sheet Track champs
A2: GAUTENG PROVINCIAL TRACK CHAMPS 2017 RECON
A4: INCOME | B4: 33021.6 | E4: Consumables
A5: Entries - Pre-Entries paid cash | B5: 4150 | E5: Game-Printing Materials | F5: 539
A6: Entries - bank deposits | B6: 22950 | C6: 82 Entries | D6: 27750 | E6: SuperSpar-Batteries | F6: 49.98
A7: Entries - Cash late entries | B7: 1750 | E7: Pnp-Toliet Paper,Refuse Bags | F7: 99.99
A8: Entries - Cash Refunds | B8: -1100
A9: Wors Rolls Sold | B9: 2265 | E9: Tvw-Toliet Paper | F9: 69.99
A10: Gate Fee (80 Cars) | B10: 2415 | E10: Pnp-Rubber Bands,Staples etc | F10: 227.73
A11: 10% Back from Coffee Stand | B11: 591.6 | F11: 986.69
E12: Wors Rolls
E13: Rolls | F13: 413
A14: EXPENSES | B14: 34140.49 | E14: Tomotoe sauce & Mustard/Sev | F14: 140.94
A15: Medals | B15: 6184.5 | C15: Pd CGC | E15: Wors | F15: 1204.9
A16: Medics | B16: 9030.51 | C16: Pd CGC | F16: 1758.84
A17: Officals 8 | B17: 10000 | C17: Pd CGC | E17: Food, drinks
A18: Food, drinks for Officials & workers | B18: 1326.12 | E18: Coffee Day 1 | F18: 350
A19: Consumables for registeration & Grounds | B19: 986.69 | E19: Coffee Day 2 | F19: 340
A20: Car guards 7 R345. each | B20: 2415 | E20: Officials | F20: 636.12
A21: Wors Rolls | B21: 1758.84 | F21: 1326.12
A22: Announcer | B22: 1500
A23: Thank you Gifts | B23: 938.83 | E23: Refunds
E24: Robbie Maartens Over paid | F24: 400
A25: NET LOSS | B25: -1118.89 | E25: Cash Refunds | F25: 700
F26: 1100

Sheet 2016 road champs
A1: Gauteng Cycle Association
A2: Internal Memo : Approval of financial results of Gauteng provincial champs 2016
A4: Objective: | B4: Present results to regions contained in Gauteng province for comment and approval
B5: Resolve on agreement by all regions to refund Central Gauteng cycling for the shortfall incurred in hosting the event
A8: Date: | B8: 42507
A10: Preliminary observations to provide context
A11: The event was initially planned to be hosted by the Sedibeng (Gauteng South) region early in January. Through Poor planning and execution the event had to be postponed twice. After the organisation again fell flat it was resolved that Central gauteng would host the event with the approval of the already established regions as it was the only region with previous experience in hosting the provincial champs and also had the spare capacity to make the necessary arrangements.
A13: Evaluation of results vs budget
E14: Actual 2016 | F14: Budget 2016 | G14: variance Favourable / (Unfavourable) | H14: Notes
A15: INCOME | E15: =SUM(E16:E18) -> 94080 | F15: =SUM(F16:F18) -> 92000 | G15: =E15-F15 -> 2080
A16: Online entries | E16: 85780 | F16: 90000 | H16: 1
A17: Office entries (R10450.00) as per cycle events. R6800.00 as per CGC acc. | E17: 6800 | H17: 1, 2
A18: Late entries - Cash | E18: 1500 | F18: 2000 | H18: 1
A20: EXPENSES | E20: =SUM(E21:E47) -> 154491.21 | F20: =SUM(F21:F47) -> 156860 | G20: =SUM(G22:G47) -> 2368.79
A21: Insurance covered by CSA
A22: Medals | E22: 4550.98 | F22: 6000 | G22: =F22-E22 -> 1449.02
A23: Medics ER24 | E23: 7612.35 | F23: 10000 | G23: =F23-E23 -> 2387.65
A24: Mardo Foto's | E24: 4500 | G24: =F24-E24 -> -4500 | H24: 3
A25: Refunds | E25: 15510 | G25: =F25-E25 -> -15510 | H25: 4
A27: Timing | F27: 10600 | G27: =F27-E27 -> 10600 | H27: 10
A30: Cycle Events 10% fee of total entries line entries
A31: 10% on entries + Vat at 14% | D31: 111740 | E31: =(D31*0.1)+(D31*0.1*0.14) -> 12738.36 | F31: 10260 | G31: =F31-E31 -> -2478.36 | H31: 5
A32: Bank charges = Vat | E32: 4338.5 | F32: 0 | G32: =F32-E32 -> -4338.5 | H32: 6
A33: Barriers | F33: 0 | G33: =F33-E33 -> 0
A34: Officials | E34: 25935 | F34: 20000 | G34: =F34-E34 -> -5935 | H34: 7
A35: Sound | G35: =F35-E35 -> 0
A36: Safety officer | E36: 4634.1 | F36: 2500 | G36: =F36-E36 -> -2134.1 | H36: 8
A37: Marshalls | E37: 2052 | F37: 0 | G37: =F37-E37 -> -2052 | H37: 8
A38: Motor Cycles (Think Bike) | D38: 10 | E38: 7500 | F38: 11000 | G38: =F38-E38 -> 3500
A39: Food and Drinks (Medics, Traffic, Officials, Think Bike) | E39: 4693.38 | F39: 3000 | G39: =F39-E39 -> -1693.38 | H39: 8
A40: Pins, Envelopes, Race numbers, Tel calls | E40: 2000 | F40: 2000 | G40: =F40-E40 -> 0 | H40: 8, 9
A41: Petrol - Route finding, marking, meetings, casuals | E41: 2500 | F41: 1500 | G41: =F41-E41 -> -1000 | H41: 9
A42: Venue Hire Boswell wilkie Circus | E42: 4560 | F42: 0 | G42: =F42-E42 -> -4560
A43: Midvaal Traffic - Saturday and Sunday | E43: 9473 | F43: 10000 | G43: =F43-E43 -> 527
A44: Dept of Road and Transport | E44: 100 | F44: 0 | G44: =F44-E44 -> -100
A45: Signage | E45: 1893.54 | F45: 0 | G45: =F45-E45 -> -1893.54 | H45: 8
A46: Organizers fee | E46: 39900 | F46: 40000 | G46: =F46-E46 -> 100 | H46: 8
A47: Jerseys | F47: 30000 | G47: =F47-E47 -> 30000 | H47: 10
A49: NET INCOME | E49: =E15-E20 -> -60411.21 | F49: =F15-F20 -> -64860 | G49: =G20+G15 -> 4448.79
A51: Payable between 5 regions | D51: Per Region | E51: =E49/5 -> -12082.242
...

Sheet cover
A4: GAUTENG CYCLING, A UNIFIED VOLUNTARY ASSOCIATION
A6: ANNUAL FINANCIAL STATEMENTS
A8: FOR THE YEAR ENDED 31 DECEMBER 2017
A10: ISSUED ON | B10: 25 April 2018

Sheet General info
A3: Country of incorporation and domicile | C3: South Africa
A5: Date of incorporation | C5: 42521
A7: Legal personality and status | C7: The Association shall be a distinct and separate legal entity and association with perpetual succession.
C8: The Association shall be an association not for gain.
C9: The income and property of the Association shall be applied solely towards the promotion of the Association as set out in the Constitution.
C10: GC is a unified voluntary association representing all cycling disciplines within the Gauteng Province as defined by Cycling South Africa ("CSA") which will be: Road cycling Track cycling Para cycling Mountain Biking Bicycle Motocross
A12: Registered office | C12: The Association's currently does not have registered offices. Based on the appointment of a Secretary at the AGM the registered offices will be assigned.
A14: Executive committee members | C14: President | D14: Chris Prinsloo (Interim)
C15: Vice President | D15: Vacant
C16: Secretary | D16: Alida Naude (Interim)
C17: Treasurer | D17: Jaco Olivier
A19: Discipline heads (Provincial Commissioners)
C20: Road | D20: Jeremy Maartens
C21: Track | D21: Vacant
C22: BMX | D22: Vacant
C23: Mountain bike | D23: Vacant
C24: Riders representative | D24: Vacant
A26: Ordinary members | C26: Regional members, being groups of cycling clubs who have formed a duly constituted and seperately recognisable legal entity representing each of the 5 regions into which the province of Gauteng has been demarkated as required by the South African Sports Confederation and Olympic Committee (SASCOC) and who have agreed to be bound by the Constitution and all rules and regulations of Gauteng Cycling, a unified provincial cycling Association ("GC"). Members comprise of the following regions:
C28: Central Gauteng Cycling ("CGC")
C29: Gauteng North Cycling ("GNC")
C30: Gauteng East Cycling ("GEC")
C31: South Gauteng Cycling ("Sedibeng")
C32: Gauteng West Cycling ("West")
C34: As at the 2017 financial year end all regions are fully formed, operating autonomously and recognised by the province with the exception of West where the region has not been able to find any volunteers to fulfill the roles of committee members. The region's affairs and responsibilities are currently being managed by CGC.
A36: Bankers | C36: Standard Bank of South Africa Ltd
A39: General objectives of GC
A40: It is the objective of Gauteng Cycling to promote, control and administer the sport of cycling (including all disciplines referred to above) within the area of jurisdiction of Gauteng Cycling in accordance with sound business principles, and without derogating from the generality of the aforesaid, shall also include the objective, through the application of sound principles, to promote: Administration of the sport; Financial management of the sport; Promotion of the sport; Development of the sport; Enforcing the rules of the sport; Transformation objectives in the sport; The prevention of discrimination in the sport; The upholding and enforcing of any code of conduct pertaining to the sport of cycling as approved by CSA and/or UCI; The recognition and acceptance of the jurisdiction, Rules, and Regulations of the South African Institute for Drug Free Sports as well as the code of the World Anti Doping Agency.
A42: Entity and Summary results | C42: Gauteng Cycling prepares financial statements that report on the financial results of the association. In order to comply with the requirements of Cycling South Africa summary results are also presented in the treasurer's report. These comprise the results of both Gauteng Cycling as well as its constituant members. It should be noted that each of these constituent members operate as autonomous organisations with their own executive committee and treasury function. Gauteng cycling does not exercise direct control over the financial affairs of any of its members and the summary results presented are merely a "sum of the parts" disclosure indicative of the total activities of the province as a whole. These summary results are included in the Treasurer's report.
A44: Auditors | C44: The auditor shall be appointed at the first annual general meeting of the Association in the manner prescribed by the constitution of GC. At date of issue of these annual financial statements the first annual general meeting is scheduled for 26 May 2018.
A46: Level of assurance | C46: These annual financial statements have not yet been audited in compliance with the applicable requirements of the constitution of GC.
A48: Preparer | C48: These annual financial statements were compiled by:
C49: Jaco Olivier Chartered Accountant (SA) in his capacity as Treasurer of GC
A51: Date of issue | C51: =cover!B10 -> 25 April 2018

Sheet Index
A3: The reports and statements set out below comprise the annual financial statements presented to
A4: the executive committee and members of Gauteng Cycling, a unified voluntary association:
A6: Index | H6: Page
A8: Independent Auditor's report | H8: 3 - 4
A10: Executive Committee's Responsibility and Approval | H10: 4
A12: Treasurer's report | H12: 5 - 8
A14: Statement of Financial Position | H14: 9
A16: Statement of Surplus or Deficit | H16: 10
A18: Statement of Changes in Available Reserves | H18: 11
A20: Statement of Cash Flows | H20: 12
A22: Accounting policies | H22: 13 - 16
A24: Notes to the Annual Financial Statements | H24: 17 - 20

Sheet Resp&Approval
A3: The executive committee is required in terms of the association's constitution to maintain adequate accounting records and are responsible for the content and integrity of the annual financial statements and related financial information included in this report. It is their responsibility to ensure that the annual financial statements fairly present the state of affairs of the association as at the end of 31 December 2017 and the results of its operations and cash flows for the period then ended, in conformity with the association's accounting policies. The independent auditor is engaged to express an opinion on the annual financial statements.
A5: The annual financial statements are prepared in accordance with the association's accounting policies and are based upon appropriate accounting policies consistently applied and supported by reasonable and prudent judgements and estimates.
A7: The executive committee acknowledges that they are ultimately responsible for the system of internal financial and operational controls established by the organisation and place considerable importance on maintaining a strong control environment. To enable the executive committee to meet these responsibilities, the committee sets standards for internal control aimed at reducing the risk of error or loss in a cost effective manner as well as ensuring compliance with the association's constitution. The standards include the proper delegation of responsibilities within a clearly defined framework, effective accounting procedures and adequate segregation of duties to ensure an acceptable level of risk. These controls are monitored throughout the association and all employees are required maintain the highest ethical standards in ensuring the association's business is conducted in a manner that in all reasonable circumstances is above reproach. The focus of risk management in the association is on identifying, assessing, managing and monitoring all known forms of risk across the association. While operating risk cannot be fully eliminated, the association endeavours to minimise it by ensuring that appropriate infrastructure, controls, systems and ethical behaviour are applied and managed within predetermined procedures and constraints.
A9: The executive committee is of the opinion, based on the information at their disposal, that the system of internal controls provide reasonable assurance that the financial records may be relied on for the preparation of the annual financial statements. However, any system of internal financial control can provide only reasonable and not absolute assurance against material misstatement or loss.
A11: The executive committee is satisfied that the association has access to adequate resources to continue in operational existence for the next twelve months.
A13: The external auditors are responsible for independently auditing and reporting on the association's annual financial statements.
A15: The annual financial statements set out on pages 9 to 20, which have been prepared on the going concern basis, were approved by the executive committee on 25 April 2018 and were signed on its behalf by:
A31: C Prinsloo (Interim President) | F31: J Olivier (Treasurer)

Sheet Treasurer report
B3: The treasurer has pleasure in submitting his report on the financial affairs of Gauteng Cycling, a unified voluntary association for the financial year ended 31 December 2017.
A5: 1. | B5: Review of activities
B7: Main business and operations
B8: The association is engaged in cycling and operates principally in Gauteng Province, South Africa.
B10: The association was recognised on 31 May 2016 as a duly recognised province by the national cycling governing body, Cycling South Africa.
B12: The operating results and state of affairs of the association are fully set out in the attached financial statements, but the Treasurer would like to highlight the following:
B14: As the association has only formally operated for 19 months leading up to the financial year ending 31 December 2017, the results presented only cover this period. As each of the constituent members have been operating autonomously for longer than 24 months leading up to 31 December 2017, the summary results presented in section 9 below are based on the operating results of a full financial year in both the representative as well as comparative period.
B16: It should be noted that all of the regions' financial year ends do not coincide with the 31 December year end of the association and as a result the summary results include a full financial year for each region, but does not cover the same calendar period. The executive committee will endeavour to align the year-ends of all regions within the province going forward.
B18: The association has realised a net deficit of funds generated amounting to R1 663 (R841 deficit for the 7 months ending 31 December 2016) and has total assets to the value of R406 (R12 001 : 2016) with liabilities exceeding assets by an amount of R2 504 (R841 : 2016).
A20: 2. | B20: Committee
B21: The committee members in office at the date of this report are as follows:
B23: President | E23: Chris Prinsloo (interim President)
B24: Vice President | E24: Vacant
B25: Secretary | E25: Alida Naude (Interim Secretary)
B26: Treasurer | E26: Jaco Olivier
B27: Commissioner - Road | E27: Jeremy Maartens
B28: Commissioner - Mountain Bike | E28: Vacant
B29: Commissioner - Track | E29: Vacant
B30: Commissioner - BMX | E30: Vacant
B32: The President was appointed upon formation of the association in the manner prescribed by the constitution. During 2017 the President tendered his resignation, due to other work commitments placing too high a demand on his time to tend to the office of the president. Subsequently the Vice President was appointed as Interim President and took over the duties of President until his resignation on 25 October 2017 at which point Chris Prinsloo was nominated by the executive to fulfill the duties of Interim President until such time as a new President can be appointed at the first AGM. As per the constitution, all members will hold office for a period of 2 years, or until the second AGM, whichever period is shorter.
A34: 3. | B34: Events after the reporting period
B35: The executive committee is not aware of any material reportable event which occurred after the reporting date and up to the date of this report which would impact on the information contained in this report.
A42: 4. | B42: Going concern
B43: The financial statements have been prepared on the basis of accounting policies applicable to a going concern. This basis presumes that funds will be available to finance future operations and that the realisation of assets and settlement of liabilities, contingent obligations and commitments will occur in the ordinary course of business.
B45: The association is committed to prudent financial management and has endeavoured to keep costs as low as what the current size and level of complexity allows for.
B47: The association anticipates that it will be able to raise the required amount of funds from its member regions in order to fund its operational requirements. Expenditure is expected to be lower than fees generated thereby allowing the association to also focus on its core responsibilities of advancing the sport of cycling through the funding of projects and events.
A49: 6. | B49: Objectives of association
B50: As is evident from the slow growth in member clubs year on year the communication and understanding difficulties are still persisting to some extent. The association is however attempting to rectify the situation by requesting member clubs to communicate the changing structures to their fellow riders and clubs that they come into contact with. The association is also slowly building a current and reliable database with contact details for both clubs and individual riders that can be included on news and event mailing lists.
B52: The level of detail, transparency and relevant information included in these financial statement are testament to the commitment of the association to continue and build on the prudent financial management of the association.
B54: The association is proud to announce that its member regions have ensured that the organization and hosting of the 2017 provincial road and time trial championships took place. This is testament to the commitment to achieving the goals set out in our constitution by being a representative for the sport, amicably communicating and collaborating with fellow regions in Gauteng province as well as contributing towards the organization of a provincial championship to recognise the best cyclists in the province.
B56: Future plans aimed at continued growth towards the goals of the association include, but are not limited to, brainstorming ideas to again build a culture of competition between regions and provinces where the riders want to be a representative for their region and proudly display its colours. We would like to clearly define a selection process with criteria that riders need to comply with in order to be eligible for selection and for riders to actively strive to meet these criteria. Building on this the association would like to pioneer a series of inter club races within the region as well as the province to start fostering this culture of regional rivalry and ultimately build towards a series of inter provincial events where riders can only participate if they are selected by their province.
A58: 7. | B58: Decisions resolved at meetings of the members
B59: During the period under review the following resolutions were proposed and passed after being carried by a vote as required in the association's constitution:
A60: i | B60: The appointment of Chris Prinsloo as Interim President after the resignation of Shahad Khan.
A62: 5. | B62: Governance
B63: The minutes of all meetings held during the course of the financial year are available upon request from the association's registered offices. The treasurer would however like to highlight the following areas of concern that have been identified relating to the financial affairs of the association:
A65: i.i | B65: The association has no means of generating its own funds without relying on funds requested from its regional members as Cycling South Africa has set up fee structures in such a way that all fees accrue directly to the regions where the riders are domiciled and not to the province thereby limiting the operational abilities of the province.
A67: i.ii | B67: Further to the above, the difficulty in reaching agreement between both the regions and CSA on the amounts owing between one another and as a result refusing to be the first to pay has placed some of the regions in a position where they struggle to raise the cash flow required to optimally execute on their constitutional mandates. All accounts between regions and CSA needs to be agreed and settled as a matter of urgency.
A72: i.iii | B72: Central Gauteng Cycling did not have a properly constituted EXCO after the resignation of Shahad Khan at the region's AGM which was held in January 2018. At the AGM the members replaced all previous members of the executive with new members and agreed in principle to pay Mr. Khan for the remaining managment fees due to him after the efficient transition and hand-over of operations to the new executive. Unfortunately the relationship between the newly appointed executive and Mr. Khan soured to the point of complete breakdown in communication and all comunication between the parties occuring through their lawyers with the new executive claiming that Mr Khan refuses to extinguish his duties in handing over all accounting records and supporting documents as well as facilitating the change of signatories on all bank accounts and Mr. Khan claiming his only assurance of receiving the remaining fees would be to demand payment before fully extinguishing his duties. Due to the circumstances above central Gauteng were limited in compiling their 2017 financial statements to relying on the accounting records and limited supporting documents handed over after the financial year-end elapsed and subsequently verifying the accuracy of theses against the bank statements available. Although the financial statements were compiled based on the bank statements and information available to the EXCO, the lack of all supporting documents being available(Supplier invoices etc) to substantiate every transaction makes it doubtful that the region will receive an unmodified audit opinion should the constitution be amended to demand an audit in terms of the International Standards of Auditing.
A74: i.iv | B74: Gauteng East unfortunately suffered the passing of their treasurer early in 2018 and due to the prolonged illness in 2017 have not been able to finalise their 2017 financials. The region has appointed a new treasurer as well as independent auditors to ensure that these matters are resolved but their financial results have not yet been included in this report at the date of issue.
...

Sheet SOFP
A2: Figures in South African Rand | F2: Note | H2: 2017 | J2: 2016
A4: ASSETS
A6: Current assets
B8: Cash and cash equivalents | F8: 2 | H8: =GC_TB_2017!G6 -> 406 | J8: =GC_TB_2016!G6 -> 12001
B9: Trade and other receivables | F9: 3 | H9: =GC_TB_2017!G5 -> 0 | J9: =GC_TB_2016!G5 -> 0
H10: =SUM(H8:H9) -> 406 | J10: =SUM(J8:J9) -> 12001
A12: Total assets | H12: =H10 -> 406 | J12: =J10 -> 12001
A14: EQUITY AND LIABILITIES
A16: Equity
B17: Accumulated surplus / (Deficit) | H17: =-GC_TB_2017!G4+SOCI!H18 -> -2504 | J17: =SOCE!J8 -> -841
A19: Liabilities
A21: Current liabilities
B22: Trade and other payables | F22: 4 | H22: =-GC_TB_2017!G7 -> 2910 | J22: =-GC_TB_2016!G7 -> 12842
A25: Total equity and liabilities | H25: =H17+H22 -> 406 | J25: =J17+J22 -> 12001

Sheet SOCI
A2: Figures in South African Rand | F2: Note | H2: 2017 | J2: 2016
A4: Revenue | F4: 5 | H4: =-GC_TB_2017!G9 -> 18000 | J4: =-GC_TB_2016!G9 -> 36247
A6: Expenditure incurred in realising the objectives of GC | F6: 6 | H6: =GC_TB_2017!G11 -> 18000 | J6: =GC_TB_2016!G11 -> 36247
A8: Gross surplus realised | H8: =H4-H6 -> 0 | J8: =J4-J6 -> 0
A10: Other income | F10: 7 | H10: 0 | J10: 0
A12: General and administrative expenses | F12: 8 | H12: =GC_TB_2017!G14 -> 1662 | J12: =GC_TB_2016!G14 -> 841
A14: Expenses for which no supporting documents are available | F14: 9 | H14: 0 | J14: 0
A16: Finance cost | H16: =GC_TB_2017!G15 -> 1 | J16: 0
A18: Surplus / (Deficit) realised for the year | H18: =H8+H10-H12-H13-H14-H16 -> -1663 | J18: =J8+J10-J12-J13-J16 -> -841

Sheet SOCE
A2: Figures in South African Rand | H2: Note | J2: Retained surplus
A4: Balance as at 31 May 2016 (date of formation) | J4: 0
A6: Surplus / (Deficit) realised for the year | J6: =SOCI!J18 -> -841
A8: Balance as at 31 December 2016 | J8: =J4+J6 -> -841
A10: Opening balance as at 1 January 2017 | J10: =J8 -> -841
A12: Surplus / (Deficit) realised for the year | J12: =SOCI!H18 -> -1663
A14: Balance as at 31 December 2017 | J14: =J10+J12 -> -2504

Sheet SCF
A2: Figures in South African Rand | F2: Note | H2: 2017 | J2: 2016
A4: Cash flows from operating activities
A6: Cash receipts from customers | H6: =Workings!D14 -> 18000 | J6: =Workings!D42 -> 36247
A7: Cash paid to suppliers and employees | H7: =Workings!D20 -> -29594 | J7: =Workings!D48 -> -24245.53
A8: Interest received | H8: 0 | J8: 0
A9: Interest paid | H9: =-SOCI!H16 -> -1 | J9: 0
A10: Income taxes paid | H10: 0 | J10: 0
A12: Net cash from (used in) operating activities | F12: 9 | H12: =SUM(H6:H10) -> -11595 | J12: =SUM(J6:J10) -> 12001.47
A14: Cash flows from investing activities
A15: Proceeds from sale of equipment | H15: 0 | J15: 0
A16: Purchases of equipment | H16: 0 | J16: 0
A18: Net cash from (used in) investing activities | H18: 0 | J18: 0
A20: Cash flows from financing activities
A21: Repayment of borrowings | H21: 0 | J21: 0
A22: Payment of finance lease obligations | H22: 0 | J22: 0
A24: Net cash from (used in) financing activities | H24: 0 | J24: 0
A26: Net increase (decrease) in cash and cash equivalents | H26: =H30-H28 -> -11595 | J26: =J12 -> 12001.47
A28: Cash and cash equivalents at beginning of year | H28: =GC_TB_2016!G6 -> 12001 | J28: 0
A30: Cash and cash equivalents at end of year | H30: =GC_TB_2017!G6 -> 406 | J30: =GC_TB_2016!G6 -> 12001

Sheet Acc policies
A3: 1. | B3: Summary of significant accounting policies
A5: 1.1 | B5: Presentation of annual financial statements
B7: The annual financial statements have been prepared in accordance with the accounting policies as set out below. The annual financial statements have been prepared on the historical cost basis, except as indicated. They are presented in South African Rands.
B9: The accounting policies have been consistently applied.
A11: 1.2 | B11: Significant judgements applied
B12: No significant judgements were made in applying the accounting policies of the association.
A14: 1.3 | B14: Key sources of estimation uncertainty
B15: No key assumptions concerning the future, and other key sources of estimation uncertainty at the reporting date have been identified, that have a significant risk of causing a material adjustment to the carrying amounts of assets and liabilities within the next financial year.
A17: 1.4 | B17: Financial instruments
B18: A financial instrument is a contract that gives rise to a financial asset of one entity and a financial liability or equity instrument of another entity.
B20: An entity shall recognise a financial asset or a financial liability only when the entity becomes a party to the contractual provisions of the instrument.
B22: When a financial asset or financial liability is recognised initially, an entity shall measure it at the transaction price (including transaction costs) unless the arrangement constitutes, in effect, a financing transaction. A financing transaction may take place in connection with the sale of goods or services, for example, if payment is deferred beyond normal business terms or is financed at a rate of interest that is not a market rate. If the arrangement constitutes a financing transaction, the entity shall measure the financial asset or financial liability at the present value of the future payments discounted at a market rate of interest for a similar debt instrument.
B24: At the end of each reporting period, an entity shall measure financial instruments as follows, without any deduction for transaction costs the entity may incur on sale or other disposal: (a) Debt instruments that meet the conditions shall be measured at amortised cost using the effective interest method. Cash and debt instruments that are classified as current assets or current liabilities shall be measured at the undiscounted amount of the cash or other consideration expected to be paid or received (i.e., net of impairment) unless the arrangement constitutes, in effect, a financing transaction. If the arrangement constitutes a financing transaction, the entity shall measure the debt instrument at the present value of the future payments discounted at a market rate of interest for a similar debt instrument.
B26: At the end of each reporting period, an entity shall assess whether there is objective evidence of impairment of any financial assets that are measured at cost or amortised cost. If there is objective evidence of impairment, the entity shall recognise an impairment loss in profit or loss immediately.
B28: If, in a subsequent period, the amount of an impairment loss decreases and the decrease can be related objectively to an event occurring after the impairment was recognised (such as an improvement in the debtor’s credit rating), the association shall reverse the previously recognised impairment loss either directly or by adjusting an allowance account. The reversal shall not result in a carrying amount of the financial asset (net of any allowance account) that exceeds what the carrying amount would have been had the impairment not previously been recognised and shall be recognised in surplus or deficit immediately.
B30: The association recognises the following financial assets and liabilities:
B32: Trade and other receivables
B33: Trade and other receivables are recognised initially at the transaction price and subsequently at the undiscounted amount of the cash or other consideration expected to be received.
A42: 1.4 | B42: Financial instruments (Continued)
B43: Trade and other payables
B44: Trade and other payables are initially measured at fair value, less any transaction costs and are subsequently measured at amortised cost, using the effective interest rate method.
B46: Cash and cash equivalents
B47: Cash and cash equivalents includes cash on hand and cash in held at financial institutions in accounts registered in the name of the association. These balances are initially and subsequently measured at their amortised cost.
B49: Other financial assets
B50: Other financial assets are measured at amortised cost using the effective interest rate method
A52: 1.5 | B52: Impairment of financial instruments
B53: The association assesses at each reporting date whether there is any objective evidence that a financial asset or group of financial assets is impaired. A financial asset or a group of financial assets is deemed to be impaired if, and only if, there is objective evidence of impairment as a result of one or more events that has occurred after the initial recognition of the asset (an incurred loss event) and that loss event has an impact on the estimated future cash flows of the financial asset or the Group of financial assets that can be reliably estimated.
B55: For financial assets carried at amortised cost the association first assesses individually whether objective evidence of impairment exists individually for financial assets that are individually significant, or collectively for financial assets that are not individually significant. If the association determines that no objective evidence of impairment exists for an individually assessed financial asset, whether significant or not, it includes the asset in a group of financial assets with similar credit risk characteristics and collectively assesses them for impairment. Assets that are individually assessed for impairment and for which an impairment loss is, or continues to be, recognised are not included in a collective assessment of impairment.
B57: If there is objective evidence that an impairment loss has been incurred, the amount of the loss is measured as the difference between the asset’s carrying amount and the present value of the estimated future cash flows (excluding future expected credit losses that have not yet been incurred). The present value of the estimated future cash flows is discounted at the financial asset’s original effective interest rate. If a loan has a variable interest rate, the discount rate for measuring any impairment loss is the current effective interest rate. The carrying amount of the asset is reduced through the use of an allowance account and the amount of the loss is recognised in surplus or deficit realised.
B59: Interest income continues to be accrued on the reduced carrying amount and is accrued using the rate of interest used to discount the future cash flows for the purpose of measuring the impairment loss. The interest income is recorded as part of finance income in the statements of profit or loss and other comprehensive income. Loans, together with the associated allowance, are written off when there is no realistic prospect of future recovery and all collateral has been realised or has been transferred to the association. If, in a subsequent year, the amount of the estimated impairment loss increases or decreases because of an event occurring after the impairment was recognised, the previously recognised impairment loss is increased or decreased by adjusting the allowance account. If a future write-off is later recovered, the recovery is credited to finance costs in the statements of surplus or deficit realised.
A61: 1.6 | B61: Offsetting of financial assets and financial liabilities
B62: Financial assets and financial liabilities are offset and the net amount reported in the statements of financial position if, and only if, there is a currently enforceable legal right to offset the recognised amounts and there is an intention to settle on a net basis, or to realise the assets and settle the liabilities simultaneously. This is most often the case in dealings with Cycling South Africa where amounts due or receivable for any given period are settled on a net basis by mutual agreement.
A73: 1.7 | B73: Revenue
B74: Revenue is recognised to the extent that it is probable that the economic benefits will flow to the association and the revenue can be reliably measured, regardless of when the payment is being made. Revenue is measured at the fair value of the consideration received or receivable and represents the amounts receivable for services provided in the normal course of business, net of discounts and value added tax (where applicable).
B76: For all financial instruments measured at amortised cost, interest income or expense is recorded using the effective interest rate (EIR), which is the rate that exactly discounts the estimated future cash payments or receipts through the expected life of the financial instrument or a shorter period, where appropriate, to the net carrying amount of the financial asset or liability. Interest income is included in other income in surplus or deficit realised.
B78: The association classifies revenue in one of the following classes:
B80: Membership fees
B81: Fees received from members on an annual or ad-hoc basis in order for them to be affiliated and recognised within the province and to enable the province to fund its operational requirements. These fees are paid in order for the regions and their clubs and riders to enjoy the support and benefits of belonging to the province as outlined in the constitution of the association.
B83: Day licence fees
B84: As all riders participating in events sanctioned and held under the rules of the national governing body will enjoy a minimum standard of prescribed benefits, the governing body requires all participants to be duly licenced riders with the national governing body. If a participant is not a licenced rider they are required to purchase a licence to participate in said sanctioned event from the governing body (a day licence).
...

Sheet Notes
A2: Figures in South African Rands | G2: 2017 | I2: 2016
A4: 2. | B4: Cash and cash equivalents
B5: Cash and cash equivalents consist of:
B7: Cash on hand | G7: 0 | I7: 0
B8: Bank balances | G8: =GC_TB_2017!G6 -> 406 | I8: =GC_TB_2016!G6 -> 12001
G9: =SUM(G7:G8) -> 406 | I9: =SUM(I7:I8) -> 12001
B10: Bank balances are held in a current account which does not earn interest.
A12: 3. | B12: Trade and other receivables
B13: Trade receivables | G13: =GC_TB_2017!G5 -> 0 | I13: =GC_TB_2016!G5 -> 0
B14: Other receivables | G14: 0 | I14: 0
G15: =SUM(G13:G14) -> 0 | I15: =SUM(I13:I14) -> 0
B16: Provision for bad debts * | G16: 0 | I16: 0
G17: =SUM(G15:G16) -> 0 | I17: =I15-I16 -> 0
A18: ** | B18: If receivables exceed 120 days ageing and as a result it is deemed that there are sufficient indicators of impairment and that these amounts may not be recoverable. The executive committee will make a concerted effort to follow up on the recovery of any amounts. Where this relates to member affiliation fees for members who no longer wish to be affiliated, or no longer exist, the receivable will be written off in the following financial year and disclosed in that year's financial statements.
A20: 4. | B20: Trade and other payables
B21: Cycling south Africa | G21: 0 | I21: 0
B22: Central Gauteng Cycling region | G22: 0 | I22: 12082.24
B23: Gauteng East Cycling region | G23: 0 | I23: 0
B24: Gauteng North Cycling region | G24: 0 | I24: 0
B25: Sedibeng Cycling region (Gauteng South) | G25: 0 | I25: 0
B26: Unutilised grants and subsidies | G26: 0 | I26: 0
B27: Trust and affiliate funds | G27: 0 | I27: 0
B28: Sundry payable * | G28: 2910 | I28: 760
G29: =SUM(G21:G28) -> 2910 | I29: =SUM(I21:I28) -> 12842.24
A30: * | B30: The GC EXCO has not yet resolved to approve any recovery of expenses from its regions except for the the recovery of expenses incurred by a region while hosting a provincial championship for any of the disciplines that the province oversees. The general expenses incurred in administrating the region have been funded by its Treasurer and will be repaid at such time when the EXCO resolves to approve the recovery of general expenses from its regions. No interest is applicable to this advance.
A32: 5. | B32: Revenue
B33: Members fees * | G33: =SUM(G34:G35) -> 18000 | I33: =SUM(I34:I35) -> 36247
B34: Recovery to reimburse Central Gauteng Cycling for net expenses incurred in hosting provincial road championships | G34: 0 | I34: =-GC_TB_2016!G9 -> 36247
B35: Recovery to reimburse Central Gauteng Cycling for net expenses incurred in hosting provincial track championships | G35: =-GC_TB_2017!G9 -> 18000 | I35: 0
B36: Calendar fees | G36: 0 | I36: 0
B37: Event participation affiliation fees | G37: 0 | I37: 0
B38: Day Licence fees | G38: 0 | I38: 0
B39: Officials' Registration & Race Fees | G39: 0 | I39: 0
B40: CSA licence affiliation distribution | G40: 0 | I40: 0
B41: Donations received | G41: 0 | I41: 0
G42: =SUM(G33,G36,G37,G38,G39,G40:G41) -> 18000 | I42: =SUM(I33,I36,I37,I38,I39,I40:I41) -> 36247
A43: * | B43: The constitution of GC enables it to recover from its members whatsoever fees the EXCO deems necessary and approves in order for the province to administer its affairs. No fixed member affiliation fees are charged at present.
A45: Figures in South African Rands | G45: 2017 | I45: 2016
A47: 6. | B47: Expenditure occurred in realising the objectives of GEC
B48: Reimburse regions for expenses incurred in hosting provincial championships | G48: 18000 | I48: 36247
...

Sheet GC_Bank_Statements
A2: Account details
A3: Bank | B3: Standard Bank
A4: Account number | B4: 30 055 999 2
A5: Account opening date | B5: 42521
A6: Overdraft rate | B6: 0.21
A7: Debit interest rate | B7: 0
A9: Statement number | B9: Date | C9: Details | D9: Debits | E9: Credits | F9: Balance | G9: Test | H9: Service fee | I9: Month end balance
A10: 1 | B10: 42521 | C10: Opening balance | D10: 0 | E10: 0 | F10: 0 | H10: 0
A11: 1 | B11: 42521 | C11: CREDIT TRANSFER 9378 INVESTECPBActivation PMT - JO | E11: 300 | F11: =F10+E11-D11 -> 300
A12: 1 | B12: 42521 | C12: CREDIT TRANSFER 9463 INVESTECPBActivation PMT - JO | E12: 100 | F12: =F11+E12-D12 -> 400
A13: 1 | B13: 42521 | C13: CREDIT TRANSFER 9465 INVESTECPBActivation PMT - JO | E13: 110 | F13: =F12+E13-D13 -> 510 | I13: =F13 -> 510
A14: 1 | B14: 42542 | C14: IB PAYMENT FROM J.OLIVIER | E14: 50 | F14: =F13+E14-D14 -> 560
A15: 2 | B15: 42548 | C15: BALANCE BROUGHT FORWARD | F15: 560 | G15: =F15-F14 -> 0
A16: 2 | B16: 42551 | C16: MONTHLY MANAGEMENT FEE ACC 300559992 | D16: 60 | F16: =F15+E16-D16 -> 500
A17: 2 | B17: 42551 | C17: SERVICE FEE MIN SF 300559992 | D17: 60 | F17: =F16+E17-D17 -> 440 | I17: =F17 -> 440
A18: 2 | B18: 42556 | C18: CREDIT TRANSFER 9183 GAUTENG EAST CYCLING | E18: 12082.24 | F18: =F17+E18-D18 -> 12522.24
A19: 2 | B19: 42556 | C19: IB PAYMENT FROM SEDIBENGCYCLINGINV 0003 | E19: 12082.24 | F19: =F18+E19-D19 -> 24604.48
A20: 3 | B20: 42577 | C20: BALANCE BROUGHT FORWARD | F20: 24604.48 | G20: =F20-F19 -> 0
A21: 3 | B21: 42581 | C21: MONTHLY MANAGEMENT FEE ACC 300559992 | D21: 60 | F21: =F20+E21-D21 -> 24544.48
A22: 3 | B22: 42581 | C22: SERVICE FEE MIN SF 300559992 | D22: 60 | F22: =F21+E22-D22 -> 24484.48 | I22: =F22 -> 24484.48
A23: 3 | B23: 42592 | C23: IB PAYMENT TO CGC REGION 263344013 | D23: 24164.48 | F23: =F22+E23-D23 -> 320 | H23: 18.3
A24: 3 | B24: 42592 | C24: FEE: PAYMENT CONFIRM - EMAIL SHAHAD KHAN | D24: 1.05 | F24: =F23+E24-D24 -> 318.95
A25: 4 | B25: 42608 | C25: BALANCE BROUGHT FORWARD | F25: 318.95 | G25: =F25-F24 -> 0
A26: 4 | B26: 42613 | C26: MONTHLY MANAGEMENT FEE ACC 300559992 | D26: 60 | F26: =F25+E26-D26 -> 258.95
A27: 4 | B27: 42613 | C27: SERVICE FEE MIN SF 300559992 | D27: 60 | F27: =F26+E27-D27 -> 198.95 | I27: =F27 -> 198.95
A28: 4 | B28: 42633 | C28: IB PAYMENT FROM J.OLIVIER | E28: 100 | F28: =F27+E28-D28 -> 298.95
A29: 5 | B29: 42639 | C29: BALANCE BROUGHT FORWARD | F29: 298.95 | G29: =F29-F28 -> 0
A30: 5 | B30: 42639 | C30: MAGTAPE CREDIT 90 INA10001 (Gauteng North) | E30: 12082.24 | F30: =F29+E30-D30 -> 12381.19
A31: 5 | B31: 42643 | C31: MONTHLY MANAGEMENT FEE ACC 300559992 | D31: 60 | F31: =F30+E31-D31 -> 12321.19
A32: 5 | B32: 42643 | C32: SERVICE FEE MIN SF 300559992 | D32: 60 | F32: =F31+E32-D32 -> 12261.19 | I32: =F32 -> 12261.19
A33: 5 | B33: 42663 | C33: IB PAYMENT FROM J.OLIVIER | E33: 100 | F33: =F32+E33-D33 -> 12361.19
A34: 6 | B34: 42669 | C34: BALANCE BROUGHT FORWARD | F34: 12361.19 | G34: =F34-F33 -> 0
A35: 6 | B35: 42674 | C35: MONTHLY MANAGEMENT FEE ACC 300559992 | D35: 60 | F35: =F34+E35-D35 -> 12301.19
A36: 6 | B36: 42674 | C36: SERVICE FEE MIN SF 300559992 | D36: 60 | F36: =F35+E36-D36 -> 12241.19 | I36: =F36 -> 12241.19
A37: 7 | B37: 42700 | C37: BALANCE BROUGHT FORWARD | F37: 12241.19 | G37: =F37-F36 -> 0
A38: 7 | B38: 42704 | C38: MONTHLY MANAGEMENT FEE ACC 300559992 | D38: 60 | F38: =F37+E38-D38 -> 12181.19
A39: 7 | B39: 42704 | C39: SERVICE FEE MIN SF 300559992 | D39: 60 | F39: =F38+E39-D39 -> 12121.19 | I39: =F39 -> 12121.19
A40: 8 | B40: 42730 | C40: BALANCE BROUGHT FORWARD | F40: 12121.19 | G40: =F40-F39 -> 0
A41: 8 | B41: 42735 | C41: MONTHLY MANAGEMENT FEE ACC 300559992 | D41: 60 | F41: =F40+E41-D41 -> 12061.19
A42: 8 | B42: 42735 | C42: SERVICE FEE MIN SF 300559992 | D42: 60 | F42: =F41+E42-D42 -> 12001.19 | I42: =F42 -> 12001.19 | J42: 2016 financial year end
...

Sheet GC_TB_2017
A1: Prepared by: Jaco Olivier
A2: Trial Balance : 01/05/2016 to 31/12/2016 | G2: GC - Provincial body
A3: Last Year | B3: Account | G3: Rounded | H3: Balance | J3: Category
A4: =GC_TB_2016!H4+SUM(GC_TB_2016!H9:H14) -> 841.05 | B4: 5200/000 | C4: Retained Income / (Accumulated Loss) | G4: =ROUND(H4,0) -> 841 | H4: =A4 -> 841.05 | J4: SOFP - Equity Reserves
A5: =GC_TB_2016!H5 -> 0 | B5: 8000/000 | C5: Customer control account | G5: =ROUND(H5,0) -> 0 | H5: =GC_GL_2017!E49 -> 0 | J5: SOFP - Current assets - Trade receivables
A6: =GC_TB_2016!H6 -> 12001.19 | B6: 8400/000 | C6: Current acc - 30 055 999 2 | G6: =ROUND(H6,0) -> 406 | H6: =GC_GL_2017!E90 -> 405.59 | J6: SOFP - Current assets - Cash
A7: =GC_TB_2016!H7 -> -12842.24 | B7: 9000/000 | C7: Supplier control account | G7: =ROUND(H7,0)+G18 -> -2910 | H7: =GC_GL_2017!E100 -> -2910 | J7: SOFP - Current liabilities - Trade payables
C8: Income
A9: =GC_TB_2016!H9 -> -36246.72 | B9: 1000/001 | C9: Fee income-recoveries charged to regions | G9: =ROUND(H9,0) -> -18000 | H9: =GC_GL_2017!E8 -> -18000 | J9: SOCI - income
C10: Expenses incurred in realising objectives of the association
A11: =GC_TB_2016!H11 -> 36246.72 | B11: 2000/001 | C11: Fee disbursement-regional expenses | G11: =ROUND(H11,0) -> 18000 | H11: =GC_GL_2017!E10 -> 18000 | J11: SOCI - expenses - incurred in realising objectives of constitution
C13: General and administrative expenses
A14: =GC_TB_2016!H14 -> 841.05 | B14: 3200/000 | C14: Bank Charges | G14: =ROUND(H14,0) -> 1662 | H14: =GC_GL_2017!E38 -> 1662.2 | J14: SOCI - Operating expense
A15: 0 | B15: 3300/000 | C15: Finance charges | G15: =ROUND(H15,0) -> 1 | H15: =GC_GL_2017!E41 -> 1.16 | J15: Rounding - taken to sundry assets/liabilities
G16: =SUM(G4:G15) -> 0 | H16: =SUM(H4:H15) -> -5.3645977e-13 | J16: Rounding - taken to sundry payables or receivables
G18: 0 | J18: Rounding

Sheet GC_GL_2017
A1: Prepared by: Jaco Olivier
A2: GL Detailed Ledger 01/05/2016 to 31/12/2016
A3: GL Code | B3: GL Description | C3: Date | D3: Entry Type | E3: Reference | F3: Contra Acc. | G3: Description | H3: Amount | I3: Cumulative balance
F4: (If Avail)
A5: 1000/001 | B5: Fee income-recoveries charged to regions | C5: 42794 | D5: DJ - Regions | E5: INA10004 | F5: 8000/000 | G5: Recovery due to CGC for hosting provincial road champs | H5: -6000 | I5: =H5 -> -6000
A6: 1000/001 | B6: Fee income-recoveries charged to regions | C6: 42794 | D6: DJ - Regions | E6: INA10005 | F6: 8000/000 | G6: Recovery due to CGC for hosting provincial road champs | H6: -6000 | I6: =I5+H6 -> -12000
A7: 1000/001 | B7: Fee income-recoveries charged to regions | C7: 42794 | D7: DJ - Regions | E7: INA10006 | F7: 8000/000 | G7: Recovery due to CGC for hosting provincial road champs | H7: -6000 | I7: =I6+H7 -> -18000
A8: 1000/001 | B8: Fee income-recoveries charged to regions | C8: Closing Balance as at 31/12/2016 | E8: =I7 -> -18000
A9: 2000/001 | B9: Fee disbursement-regional expenses | C9: 42794 | D9: CJ - Regions | E9: INC10002 | F9: 9000/000 | G9: CGC reimbursed for expenses incurred in hosting provincial track champs | H9: 18000 | I9: =H9 -> 18000
A10: 2000/001 | B10: Fee disbursement-regional expenses | C10: Closing Balance as at 31/12/2016 | E10: =I9 -> 18000
A11: 3200/000 | B11: Bank Charges | C11: 42766 | D11: CPJ - Standardbank | E11: 9 | F11: 8400/000 | G11: MONTHLY MANAGEMENT FEE ACC 300559992 | H11: 69 | I11: =H11 -> 69
A12: 3200/000 | B12: Bank Charges | C12: 42766 | D12: CPJ - Standardbank | E12: 9 | F12: 8400/000 | G12: SERVICE FEE MIN SF 300559992 | H12: 64 | I12: =I11+H12 -> 133
A13: 3200/000 | B13: Bank Charges | C13: 42794 | D13: CPJ - Standardbank | E13: 10 | F13: 8400/000 | G13: MONTHLY MANAGEMENT FEE ACC 300559992 | H13: 69 | I13: =I12+H13 -> 202
A14: 3200/000 | B14: Bank Charges | C14: 42794 | D14: CPJ - Standardbank | E14: 10 | F14: 8400/000 | G14: SERVICE FEE MIN SF 300559992 | H14: 64 | I14: =I13+H14 -> 266
A15: 3200/000 | B15: Bank Charges | C15: 42795 | D15: CPJ - Standardbank | E15: 10 | F15: 8400/000 | G15: FEE: PAYMENT CONFIRM - EMAIL SHAHAD KHAN | H15: 1.1 | I15: =I14+H15 -> 267.1
A16: 3200/000 | B16: Bank Charges | C16: 42797 | D16: CPJ - Standardbank | E16: 10 | F16: 8400/000 | G16: FEE: PAYMENT CONFIRM - EMAIL SHAHAD KHAN | H16: 1.1 | I16: =I15+H16 -> 268.2
A17: 3200/000 | B17: Bank Charges | C17: 42825 | D17: CPJ - Standardbank | E17: 11 | F17: 8400/000 | G17: MONTHLY MANAGEMENT FEE ACC 300559992 | H17: 69 | I17: =I16+H17 -> 337.2
A18: 3200/000 | B18: Bank Charges | C18: 42825 | D18: CPJ - Standardbank | E18: 11 | F18: 8400/000 | G18: SERVICE FEE MIN SF 300559992 | H18: 64 | I18: =I17+H18 -> 401.2
A19: 3200/000 | B19: Bank Charges | C19: 42854 | D19: CPJ - Standardbank | E19: 12 | F19: 8400/000 | G19: MONTHLY MANAGEMENT FEE ACC 300559992 | H19: 69 | I19: =I18+H19 -> 470.2
A20: 3200/000 | B20: Bank Charges | C20: 42854 | D20: CPJ - Standardbank | E20: 12 | F20: 8400/000 | G20: SERVICE FEE MIN SF 300559992 | H20: 64 | I20: =I19+H20 -> 534.2
A21: 3200/000 | B21: Bank Charges | C21: 42886 | D21: CPJ - Standardbank | E21: 13 | F21: 8400/000 | G21: MONTHLY MANAGEMENT FEE ACC 300559992 | H21: 69 | I21: =I20+H21 -> 603.2
A22: 3200/000 | B22: Bank Charges | C22: 42886 | D22: CPJ - Standardbank | E22: 13 | F22: 8400/000 | G22: SERVICE FEE MIN SF 300559992 | H22: 64 | I22: =I21+H22 -> 667.2
A23: 3200/000 | B23: Bank Charges | C23: 42916 | D23: CPJ - Standardbank | E23: 14 | F23: 8400/000 | G23: MONTHLY MANAGEMENT FEE ACC 300559992 | H23: 69 | I23: =I22+H23 -> 736.2
... A37: 3200/000 | B37: Bank Charges | C37: 43099 | D37: CPJ - Standardbank | E37: 20 | F37: 8400/000 | G37: SERVICE FEE MIN SF 300559992 | H37: 64 | I37: =I36+H37 -> 1662.2
A38: 3200/000 | B38: Bank Charges | C38: Closing Balance as at 31/12/2016 | E38: =I37 -> 1662.2 | H38: 0
A39: 3300/000 | B39: Finance charges | C39: 42972 | D39: CPJ - Standardbank | E39: 15 | F39: 8400/000 | G39: INTEREST ON OVERDRAFT UP TO 07 31 300559992 @20,750% | H39: 0.06 | I39: =H39 -> 0.06
A40: 3300/000 | B40: Finance charges | C40: 42972 | D40: CPJ - Standardbank | E40: 15 | F40: 8400/000 | G40: INTEREST ON OVERDRAFT UP TO 08 24 300559992 @20,750% | H40: 1.1 | I40: =I39+H40 -> 1.16
A41: 3300/000 | B41: Finance charges | C41: Closing Balance as at 31/12/2016 | E41: =I40 -> 1.16
A42: 8000/000 | B42: Customer control account | C42: Opening balance as at 01/01/2017 | E42: =GC_TB_2016!H5 -> 0
A43: 8000/000 | B43: Customer control account | C43: 42794 | D43: DJ - Regions | E43: INA10004 | F43: 1000/001 | G43: Recovery due to CGC for hosting provincial track champs | H43: 6000 | I43: =H43+E42 -> 6000
A44: 8000/000 | B44: Customer control account | C44: 42794 | D44: DJ - Regions | E44: INA10005 | F44: 1000/001 | G44: Recovery due to CGC for hosting provincial track champs | H44: 6000 | I44: =I43+H44 -> 12000
A45: 8000/000 | B45: Customer control account | C45: 42794 | D45: DJ - Regions | E45: INA10006 | F45: 1000/001 | G45: Recovery due to CGC for hosting provincial track champs | H45: 6000 | I45: =I44+H45 -> 18000
A46: 8000/000 | B46: Customer control account | C46: 42795 | D46: CRJ - Standardbank | E46: 10 | F46: 8400/000 | G46: CREDIT TRANSFER 9641 ABSA BANK INA 10007 | H46: -6000 | I46: =I45+H46 -> 12000
A47: 8000/000 | B47: Customer control account | C47: 42795 | D47: CRJ - Standardbank | E47: 10 | F47: 8400/000 | G47: IB PAYMENT FROM SEDIBENG C SA'SINA10008 | H47: -6000 | I47: =I46+H47 -> 6000
A48: 8000/000 | B48: Customer control account | C48: 42796 | D48: CRJ - Standardbank | E48: 10 | F48: 8400/000 | G48: MAGTAPE CREDIT 9581 INA10006 | H48: -6000 | I48: =I47+H48 -> 0
A49: 8000/000 | B49: Customer control account | C49: Closing Balance as at 31/12/2016 | E49: =I48 -> 0
A50: 8400/000 | B50: Current acc - 30 055 999 2 | C50: Opening balance as at 01/01/2017 | E50: =GC_TB_2016!H6 -> 12001.19
A51: 8400/000 | B51: Current acc - 30 055 999 2 | C51: 42755 | D51: CRJ - Standardbank | E51: 8 | F51: 9000/000 | G51: IB PAYMENT FROM J.OLIVIER | H51: 500 | I51: =E50+H51 -> 12501.19
A52: 8400/000 | B52: Current acc - 30 055 999 2 | C52: 42766 | D52: CPJ - Standardbank | E52: 9 | F52: 3200/000 | G52: MONTHLY MANAGEMENT FEE ACC 300559992 | H52: -69 | I52: =I51+H52 -> 12432.19
A53: 8400/000 | B53: Current acc - 30 055 999 2 | C53: 42766 | D53: CPJ - Standardbank | E53: 9 | F53: 3200/000 | G53: SERVICE FEE MIN SF 300559992 | H53: -64 | I53: =I52+H53 -> 12368.19
...

Sheet GC_GL_2016
A1: Prepared by: Jaco Olivier
A2: GL Detailed Ledger 01/05/2016 to 31/12/2016
A3: GL Code | B3: GL Description | C3: Date | D3: Entry Type | E3: Reference | F3: Contra Acc. | G3: Description | H3: Amount | I3: Cumulative balance
F4: (If Avail)
A5: 1000/001 | B5: Fee income-recoveries charged to regions | C5: 42552 | D5: DJ - Regions | E5: INA10001 | F5: 8000/000 | G5: Recovery due to CGC for hosting provincial road champs | H5: -12082.24 | I5: =H5 -> -12082.24
A6: 1000/001 | B6: Fee income-recoveries charged to regions | C6: 42552 | D6: DJ - Regions | E6: INA10002 | F6: 8000/000 | G6: Recovery due to CGC for hosting provincial road champs | H6: -12082.24 | I6: =I5+H6 -> -24164.48
A7: 1000/001 | B7: Fee income-recoveries charged to regions | C7: 42552 | D7: DJ - Regions | E7: INA10003 | F7: 8000/000 | G7: Recovery due to CGC for hosting provincial road champs | H7: -12082.24 | I7: =I6+H7 -> -36246.72
A8: 1000/001 | B8: Fee income-recoveries charged to regions | C8: Closing Balance as at 31/12/2016 | E8: =I7 -> -36246.72
